<!DOCTYPE html>
<html lang="en">
	<head>
		<meta charset="UTF-8" />
		<meta http-equiv="X-UA-Compatible" content="IE=edge" />
		<meta name="viewport" content="width=device-width, initial-scale=1.0" />
		<title>async-await</title>
	</head>
	<body>
		<script>
			/* function loadJson(url) {
				return fetch(url).then((response) => {
					if (response.status == 200) {
						return response.json()
					} else {
						throw new Error(response.status)
					}
				})
			}

			loadJson("no-such-user.json") // (3)
				.catch(alert) // Error: 404 */

			async function loadJson1(url) {
				let response = await fetch(url)

				if (response.status == 200) {
					const data = await response.json()
					return data
				} else {
					await Promise.reject(new Error(response.status))
				}
			}

			loadJson1("no-such-user2.json") // (3)
				//loadJson("no-such-user.json") // (3)
				.then(console.log)
				.catch(console.log) // Error: 404

			/* Ниже пример из раздела Цепочка промисов, перепишите его, используя async/await вместо .then/catch.

			 В функции demoGithubUser замените рекурсию на цикл: используя async/await, сделать это будет просто. */

			/* class HttpError extends Error {
				constructor(response) {
					super(`${response.status} for ${response.url}`)
					this.name = "HttpError"
					this.response = response
				}
			}

			function loadJson(url) {
				return fetch(url).then((response) => {
					if (response.status == 200) {
						return response.json()
					} else {
						throw new HttpError(response)
					}
				})
			}

			// Запрашивать логин, пока github не вернёт существующего пользователя.
			function demoGithubUser() {
				let name = prompt("Введите логин?", "iliakan")

				return loadJson(`https://api.github.com/users/${name}`)
					.then((user) => {
						alert(`Полное имя: ${user.name}.`)
						return user
					})
					.catch((err) => {
						if (err instanceof HttpError && err.response.status == 404) {
							alert("Такого пользователя не существует, пожалуйста, повторите ввод.")
							return demoGithubUser()
						} else {
							throw err
						}
					})
			}

			demoGithubUser() */

			class HttpError extends Error {
				constructor(response) {
					super(`${response.status} for ${response.url}`)
					this.name = "HttpError"
					this.response = response
				}
			}

			async function loadJson(url) {
				let response = await fetch(url)
				if (response.status == 200) {
					const data = await response.json()
					return data
				} else {
					throw new HttpError(response)
				}
			}

			// Запрашивать логин, пока github не вернёт существующего пользователя.
			async function demoGithubUser() {
				let user

				while (true) {
					let name = prompt("Введите логин?", "DmytroPetrenko123213")
					try {
						user = await loadJson(`https://api.github.com/users/${name}`)
						break
					} catch (err) {
						if (err instanceof HttpError && err.response.status == 404) {
							// после alert начнётся новая итерация цикла
							alert("Такого пользователя не существует, пожалуйста, повторите ввод.")
						} else {
							// неизвестная ошибка, пробрасываем её
							throw err
						}
					}
				}
				console.log(`Полное имя: ${user.name}.`)
				return user
			}

			demoGithubUser()

			/* Есть «обычная» функция. Как можно внутри неё получить результат выполнения async–функции? */

			async function wait() {
				await new Promise((resolve) => setTimeout(resolve, 1000))

				return 10
			}

			function f() {
				// ...что здесь написать?
				// чтобы вызвать wait() и дождаться результата "10" от async–функции
				// не забывайте, здесь нельзя использовать "await"

        // сам не догадался
				wait().then((result) => console.log(result))
			}

			f()
		</script>
	</body>
</html>
